Workbook

Sheet Start here
A1: FREE DOWNLOAD · SAME WAR, NEW WEAPONS · MEASUREMENT & DATA
A2: Dayparting Analysis Template
A3: Split your Google Ads results by day and hour, compare cost per lead and conversion rate, and see which patterns repeat week after week. Companion to "The Sunday Problem".
B6: HOW TO USE THIS TEMPLATE
B7: 1. In Google Ads, open your campaign and go to the ad schedule report (day and hour view). Set the date range to the last 8 to 12 weeks.
B8: 2. Tab "Day of week": enter clicks, cost, and conversions for each day. If you can, add qualified leads and sales for each day from your CRM.
B9: 3. Tab "12-week pattern": enter cost and conversions for each day of each week. This shows whether a weak day is a pattern or a one-off.
B10: 4. Tab "Hour of day": enter clicks, cost, and conversions by hour, and mark the hours your team can answer calls.
B11: 5. Read the flags, then use tab "Decision guide" to choose what to change. Change one thing, test it for four weeks, and measure the whole week.
B13: LEGEND
B14: Lavender cell, blue text | C14: Your data goes here
B15: White cell, dark text | C15: Calculated for you. Do not overwrite.
B16: 0.15 | C16: Flag threshold: a day or hour whose cost per lead is this much above (or below) the average is flagged Weak (or Strong). Change it if you like.
B18: EXAMPLE OF THE EXPECTED FORMAT (illustrative figures, not real data)
B19: Day | C19: Clicks | D19: Cost (₹) | E19: Conversions | F19: Cost per lead
B20: Wednesday | C20: 400 | D20: 16000 | E20: 20 | F20: =IFERROR(D20/E20,"") -> 800
B21: Sunday | C21: 420 | D21: 16800 | E21: 14 | F21: =IFERROR(D21/E21,"") -> 1200
B23: READ BEFORE YOU ACT
B24: • Judge days on conversions, not clicks. A day with cheap clicks and no leads is not a good day.
B25: • Act only on patterns that repeat for at least eight weeks and survive a check on lead quality.
B26: • Smart Bidding (Maximize conversions, Target CPA, Target ROAS) does not use manual ad schedule bid adjustments; it already adjusts bids by time of day. It does follow the schedule itself, so your levers are: excluding hours, shifting budget, changing the message, and fixing follow-up.
B27: • Google Ads reports a conversion on the date the ad was shown. A Sunday click that becomes a Monday lead is counted on Sunday in Google Ads, and on Monday in most other tools.
B28: • Re-read the pattern every quarter and compare like with like: festival weeks, admission seasons, and long weekends shift the weekly rhythm.
B30: Read the full article: The Sunday Problem
B31: Need help reading your account? Talk to us about an optimization sprint
B33: MagicWorks IT Solutions · Evolving with Purpose

Sheet Day of week
A1: FREE DOWNLOAD · SAME WAR, NEW WEAPONS · MEASUREMENT & DATA
A2: Day of week
A3: Enter 8 to 12 weeks of totals for each day. Cost per lead is compared with the average across all days.
A6: Day | B6: Clicks | C6: Cost (₹) | D6: Conversions | E6: Qualified leads (CRM, optional) | F6: Sales (CRM, optional) | G6: Conversion rate | H6: Cost per lead | I6: vs average cost per lead | J6: Cost per qualified lead | K6: Lead-to-sale rate | L6: Flag
A7: Monday | G7: =IFERROR(D7/B7,"") | H7: =IFERROR(C7/D7,"") | I7: =IFERROR(H7/$H$14-1,"") | J7: =IF(E7="","",IFERROR(C7/E7,"")) | K7: =IF(OR(E7="",F7=""),"",IFERROR(F7/E7,"")) | L7: =IF(I7="","",IF(I7>'Start here'!$B$16,"Weak",IF(I7<-'Start here'!$B$16,"Strong","Normal")))
A8: Tuesday | G8: =IFERROR(D8/B8,"") | H8: =IFERROR(C8/D8,"") | I8: =IFERROR(H8/$H$14-1,"") | J8: =IF(E8="","",IFERROR(C8/E8,"")) | K8: =IF(OR(E8="",F8=""),"",IFERROR(F8/E8,"")) | L8: =IF(I8="","",IF(I8>'Start here'!$B$16,"Weak",IF(I8<-'Start here'!$B$16,"Strong","Normal")))
A9: Wednesday | G9: =IFERROR(D9/B9,"") | H9: =IFERROR(C9/D9,"") | I9: =IFERROR(H9/$H$14-1,"") | J9: =IF(E9="","",IFERROR(C9/E9,"")) | K9: =IF(OR(E9="",F9=""),"",IFERROR(F9/E9,"")) | L9: =IF(I9="","",IF(I9>'Start here'!$B$16,"Weak",IF(I9<-'Start here'!$B$16,"Strong","Normal")))
A10: Thursday | G10: =IFERROR(D10/B10,"") | H10: =IFERROR(C10/D10,"") | I10: =IFERROR(H10/$H$14-1,"") | J10: =IF(E10="","",IFERROR(C10/E10,"")) | K10: =IF(OR(E10="",F10=""),"",IFERROR(F10/E10,"")) | L10: =IF(I10="","",IF(I10>'Start here'!$B$16,"Weak",IF(I10<-'Start here'!$B$16,"Strong","Normal")))
A11: Friday | G11: =IFERROR(D11/B11,"") | H11: =IFERROR(C11/D11,"") | I11: =IFERROR(H11/$H$14-1,"") | J11: =IF(E11="","",IFERROR(C11/E11,"")) | K11: =IF(OR(E11="",F11=""),"",IFERROR(F11/E11,"")) | L11: =IF(I11="","",IF(I11>'Start here'!$B$16,"Weak",IF(I11<-'Start here'!$B$16,"Strong","Normal")))
A12: Saturday | G12: =IFERROR(D12/B12,"") | H12: =IFERROR(C12/D12,"") | I12: =IFERROR(H12/$H$14-1,"") | J12: =IF(E12="","",IFERROR(C12/E12,"")) | K12: =IF(OR(E12="",F12=""),"",IFERROR(F12/E12,"")) | L12: =IF(I12="","",IF(I12>'Start here'!$B$16,"Weak",IF(I12<-'Start here'!$B$16,"Strong","Normal")))
A13: Sunday | G13: =IFERROR(D13/B13,"") | H13: =IFERROR(C13/D13,"") | I13: =IFERROR(H13/$H$14-1,"") | J13: =IF(E13="","",IFERROR(C13/E13,"")) | K13: =IF(OR(E13="",F13=""),"",IFERROR(F13/E13,"")) | L13: =IF(I13="","",IF(I13>'Start here'!$B$16,"Weak",IF(I13<-'Start here'!$B$16,"Strong","Normal")))
A14: All days | B14: =IF(COUNT(B7:B13)=0,"",SUM(B7:B13)) | C14: =IF(COUNT(C7:C13)=0,"",SUM(C7:C13)) | D14: =IF(COUNT(D7:D13)=0,"",SUM(D7:D13)) | E14: =IF(COUNT(E7:E13)=0,"",SUM(E7:E13)) | F14: =IF(COUNT(F7:F13)=0,"",SUM(F7:F13)) | G14: =IFERROR(D14/B14,"") | H14: =IFERROR(C14/D14,"") | J14: =IF(E14="","",IFERROR(C14/E14,"")) | K14: =IF(OR(E14="",F14=""),"",IFERROR(F14/E14,""))
A16: How to read this
A17: • Weak = cost per lead more than the threshold above the all-days average (set on "Start here"). Strong = more than the threshold below it.
A18: • If you add CRM data, check cost per qualified lead too. A day with cheap leads nobody closes is a weak day in disguise.
A19: • One tab is a summary. Before acting, confirm the pattern repeats on the "12-week pattern" tab.

Sheet 12-week pattern
A1: FREE DOWNLOAD · SAME WAR, NEW WEAPONS · MEASUREMENT & DATA
A2: 12-week pattern
A3: Enter cost and conversions for each day of each week. The sheet marks the costliest and cheapest day of every week, then counts how often each day repeats.
A6: Cost (₹) by day
A7: Week | B7: Monday | C7: Tuesday | D7: Wednesday | E7: Thursday | F7: Friday | G7: Saturday | H7: Sunday
A8: Week 1
A9: Week 2
A10: Week 3
A11: Week 4
A12: Week 5
A13: Week 6
A14: Week 7
A15: Week 8
A16: Week 9
A17: Week 10
A18: Week 11
A19: Week 12
A22: Conversions by day
A23: Week | B23: Monday | C23: Tuesday | D23: Wednesday | E23: Thursday | F23: Friday | G23: Saturday | H23: Sunday
A24: Week 1
A25: Week 2
A26: Week 3
A27: Week 4
A28: Week 5
A29: Week 6
A30: Week 7
A31: Week 8
A32: Week 9
A33: Week 10
A34: Week 11
A35: Week 12
A38: Cost per lead (calculated)
A39: Week | B39: Monday | C39: Tuesday | D39: Wednesday | E39: Thursday | F39: Friday | G39: Saturday | H39: Sunday
A40: Week 1 | B40: =IF(OR(B8="",B24="",B24=0),"",B8/B24) | C40: =IF(OR(C8="",C24="",C24=0),"",C8/C24) | D40: =IF(OR(D8="",D24="",D24=0),"",D8/D24) | E40: =IF(OR(E8="",E24="",E24=0),"",E8/E24) | F40: =IF(OR(F8="",F24="",F24=0),"",F8/F24) | G40: =IF(OR(G8="",G24="",G24=0),"",G8/G24) | H40: =IF(OR(H8="",H24="",H24=0),"",H8/H24)
A41: Week 2 | B41: =IF(OR(B9="",B25="",B25=0),"",B9/B25) | C41: =IF(OR(C9="",C25="",C25=0),"",C9/C25) | D41: =IF(OR(D9="",D25="",D25=0),"",D9/D25) | E41: =IF(OR(E9="",E25="",E25=0),"",E9/E25) | F41: =IF(OR(F9="",F25="",F25=0),"",F9/F25) | G41: =IF(OR(G9="",G25="",G25=0),"",G9/G25) | H41: =IF(OR(H9="",H25="",H25=0),"",H9/H25)
A42: Week 3 | B42: =IF(OR(B10="",B26="",B26=0),"",B10/B26) | C42: =IF(OR(C10="",C26="",C26=0),"",C10/C26) | D42: =IF(OR(D10="",D26="",D26=0),"",D10/D26) | E42: =IF(OR(E10="",E26="",E26=0),"",E10/E26) | F42: =IF(OR(F10="",F26="",F26=0),"",F10/F26) | G42: =IF(OR(G10="",G26="",G26=0),"",G10/G26) | H42: =IF(OR(H10="",H26="",H26=0),"",H10/H26)
A43: Week 4 | B43: =IF(OR(B11="",B27="",B27=0),"",B11/B27) | C43: =IF(OR(C11="",C27="",C27=0),"",C11/C27) | D43: =IF(OR(D11="",D27="",D27=0),"",D11/D27) | E43: =IF(OR(E11="",E27="",E27=0),"",E11/E27) | F43: =IF(OR(F11="",F27="",F27=0),"",F11/F27) | G43: =IF(OR(G11="",G27="",G27=0),"",G11/G27) | H43: =IF(OR(H11="",H27="",H27=0),"",H11/H27)
A44: Week 5 | B44: =IF(OR(B12="",B28="",B28=0),"",B12/B28) | C44: =IF(OR(C12="",C28="",C28=0),"",C12/C28) | D44: =IF(OR(D12="",D28="",D28=0),"",D12/D28) | E44: =IF(OR(E12="",E28="",E28=0),"",E12/E28) | F44: =IF(OR(F12="",F28="",F28=0),"",F12/F28) | G44: =IF(OR(G12="",G28="",G28=0),"",G12/G28) | H44: =IF(OR(H12="",H28="",H28=0),"",H12/H28)
A45: Week 6 | B45: =IF(OR(B13="",B29="",B29=0),"",B13/B29) | C45: =IF(OR(C13="",C29="",C29=0),"",C13/C29) | D45: =IF(OR(D13="",D29="",D29=0),"",D13/D29) | E45: =IF(OR(E13="",E29="",E29=0),"",E13/E29) | F45: =IF(OR(F13="",F29="",F29=0),"",F13/F29) | G45: =IF(OR(G13="",G29="",G29=0),"",G13/G29) | H45: =IF(OR(H13="",H29="",H29=0),"",H13/H29)
A46: Week 7 | B46: =IF(OR(B14="",B30="",B30=0),"",B14/B30) | C46: =IF(OR(C14="",C30="",C30=0),"",C14/C30) | D46: =IF(OR(D14="",D30="",D30=0),"",D14/D30) | E46: =IF(OR(E14="",E30="",E30=0),"",E14/E30) | F46: =IF(OR(F14="",F30="",F30=0),"",F14/F30) | G46: =IF(OR(G14="",G30="",G30=0),"",G14/G30) | H46: =IF(OR(H14="",H30="",H30=0),"",H14/H30)
...

Sheet Hour of day
A1: FREE DOWNLOAD · SAME WAR, NEW WEAPONS · MEASUREMENT & DATA
A2: Hour of day
A3: Enter totals for each hour over the same 8 to 12 weeks. Mark the hours your team can answer calls, so call ads do not run into an empty line.
A6: Hour | B6: Clicks | C6: Cost (₹) | D6: Conversions | E6: Team answers calls? (Y/N) | F6: Conversion rate | G6: Cost per lead | H6: vs average cost per lead | I6: Flag
A7: 00:00 to 00:59 | F7: =IFERROR(D7/B7,"") | G7: =IFERROR(C7/D7,"") | H7: =IFERROR(G7/$G$31-1,"") | I7: =IF(AND(UPPER(E7)="N",N(B7)>0),"Clicks when calls go unanswered",IF(AND(N(B7)>0,N(D7)=0),"Clicks, no conversions",IF(H7="","",IF(H7>'Start here'!$B$16,"Weak",IF(H7<-'Start here'!$B$16,"Strong","Normal")))))
A8: 01:00 to 01:59 | F8: =IFERROR(D8/B8,"") | G8: =IFERROR(C8/D8,"") | H8: =IFERROR(G8/$G$31-1,"") | I8: =IF(AND(UPPER(E8)="N",N(B8)>0),"Clicks when calls go unanswered",IF(AND(N(B8)>0,N(D8)=0),"Clicks, no conversions",IF(H8="","",IF(H8>'Start here'!$B$16,"Weak",IF(H8<-'Start here'!$B$16,"Strong","Normal")))))
A9: 02:00 to 02:59 | F9: =IFERROR(D9/B9,"") | G9: =IFERROR(C9/D9,"") | H9: =IFERROR(G9/$G$31-1,"") | I9: =IF(AND(UPPER(E9)="N",N(B9)>0),"Clicks when calls go unanswered",IF(AND(N(B9)>0,N(D9)=0),"Clicks, no conversions",IF(H9="","",IF(H9>'Start here'!$B$16,"Weak",IF(H9<-'Start here'!$B$16,"Strong","Normal")))))
A10: 03:00 to 03:59 | F10: =IFERROR(D10/B10,"") | G10: =IFERROR(C10/D10,"") | H10: =IFERROR(G10/$G$31-1,"") | I10: =IF(AND(UPPER(E10)="N",N(B10)>0),"Clicks when calls go unanswered",IF(AND(N(B10)>0,N(D10)=0),"Clicks, no conversions",IF(H10="","",IF(H10>'Start here'!$B$16,"Weak",IF(H10<-'Start here'!$B$16,"Strong","Normal")))))
A11: 04:00 to 04:59 | F11: =IFERROR(D11/B11,"") | G11: =IFERROR(C11/D11,"") | H11: =IFERROR(G11/$G$31-1,"") | I11: =IF(AND(UPPER(E11)="N",N(B11)>0),"Clicks when calls go unanswered",IF(AND(N(B11)>0,N(D11)=0),"Clicks, no conversions",IF(H11="","",IF(H11>'Start here'!$B$16,"Weak",IF(H11<-'Start here'!$B$16,"Strong","Normal")))))
A12: 05:00 to 05:59 | F12: =IFERROR(D12/B12,"") | G12: =IFERROR(C12/D12,"") | H12: =IFERROR(G12/$G$31-1,"") | I12: =IF(AND(UPPER(E12)="N",N(B12)>0),"Clicks when calls go unanswered",IF(AND(N(B12)>0,N(D12)=0),"Clicks, no conversions",IF(H12="","",IF(H12>'Start here'!$B$16,"Weak",IF(H12<-'Start here'!$B$16,"Strong","Normal")))))
A13: 06:00 to 06:59 | F13: =IFERROR(D13/B13,"") | G13: =IFERROR(C13/D13,"") | H13: =IFERROR(G13/$G$31-1,"") | I13: =IF(AND(UPPER(E13)="N",N(B13)>0),"Clicks when calls go unanswered",IF(AND(N(B13)>0,N(D13)=0),"Clicks, no conversions",IF(H13="","",IF(H13>'Start here'!$B$16,"Weak",IF(H13<-'Start here'!$B$16,"Strong","Normal")))))
A14: 07:00 to 07:59 | F14: =IFERROR(D14/B14,"") | G14: =IFERROR(C14/D14,"") | H14: =IFERROR(G14/$G$31-1,"") | I14: =IF(AND(UPPER(E14)="N",N(B14)>0),"Clicks when calls go unanswered",IF(AND(N(B14)>0,N(D14)=0),"Clicks, no conversions",IF(H14="","",IF(H14>'Start here'!$B$16,"Weak",IF(H14<-'Start here'!$B$16,"Strong","Normal")))))
A15: 08:00 to 08:59 | F15: =IFERROR(D15/B15,"") | G15: =IFERROR(C15/D15,"") | H15: =IFERROR(G15/$G$31-1,"") | I15: =IF(AND(UPPER(E15)="N",N(B15)>0),"Clicks when calls go unanswered",IF(AND(N(B15)>0,N(D15)=0),"Clicks, no conversions",IF(H15="","",IF(H15>'Start here'!$B$16,"Weak",IF(H15<-'Start here'!$B$16,"Strong","Normal")))))
A16: 09:00 to 09:59 | F16: =IFERROR(D16/B16,"") | G16: =IFERROR(C16/D16,"") | H16: =IFERROR(G16/$G$31-1,"") | I16: =IF(AND(UPPER(E16)="N",N(B16)>0),"Clicks when calls go unanswered",IF(AND(N(B16)>0,N(D16)=0),"Clicks, no conversions",IF(H16="","",IF(H16>'Start here'!$B$16,"Weak",IF(H16<-'Start here'!$B$16,"Strong","Normal")))))
A17: 10:00 to 10:59 | F17: =IFERROR(D17/B17,"") | G17: =IFERROR(C17/D17,"") | H17: =IFERROR(G17/$G$31-1,"") | I17: =IF(AND(UPPER(E17)="N",N(B17)>0),"Clicks when calls go unanswered",IF(AND(N(B17)>0,N(D17)=0),"Clicks, no conversions",IF(H17="","",IF(H17>'Start here'!$B$16,"Weak",IF(H17<-'Start here'!$B$16,"Strong","Normal")))))
A18: 11:00 to 11:59 | F18: =IFERROR(D18/B18,"") | G18: =IFERROR(C18/D18,"") | H18: =IFERROR(G18/$G$31-1,"") | I18: =IF(AND(UPPER(E18)="N",N(B18)>0),"Clicks when calls go unanswered",IF(AND(N(B18)>0,N(D18)=0),"Clicks, no conversions",IF(H18="","",IF(H18>'Start here'!$B$16,"Weak",IF(H18<-'Start here'!$B$16,"Strong","Normal")))))
... A30: 23:00 to 23:59 | F30: =IFERROR(D30/B30,"") | G30: =IFERROR(C30/D30,"") | H30: =IFERROR(G30/$G$31-1,"") | I30: =IF(AND(UPPER(E30)="N",N(B30)>0),"Clicks when calls go unanswered",IF(AND(N(B30)>0,N(D30)=0),"Clicks, no conversions",IF(H30="","",IF(H30>'Start here'!$B$16,"Weak",IF(H30<-'Start here'!$B$16,"Strong","Normal")))))
A31: All hours | B31: =IF(COUNT(B7:B30)=0,"",SUM(B7:B30)) | C31: =IF(COUNT(C7:C30)=0,"",SUM(C7:C30)) | D31: =IF(COUNT(D7:D30)=0,"",SUM(D7:D30)) | F31: =IFERROR(D31/B31,"") | G31: =IFERROR(C31/D31,"")

Sheet Decision guide
A1: FREE DOWNLOAD · SAME WAR, NEW WEAPONS · MEASUREMENT & DATA
A2: Decision guide
A3: What to do once a pattern is clear. The right move depends on how the campaign bids.
A6: What you see | B6: On manual or clicks-based bidding | C6: On Smart Bidding
A7: A day costs more every week | B7: Lower that day’s bid in modest steps, then review after two to four weeks | C7: Change the message for that day, or shift budget toward what works on strong days
A8: Some hours never convert | B8: Lower bids for those hours | C8: Exclude those hours from the ad schedule
A9: Calls arrive when nobody answers | B9: Match the ad schedule to the hours your team can respond | C9: Match the ad schedule to the hours your team can respond
A10: Leads go cold before follow-up | B10: Fix sales response time first | C10: Fix sales response time first
A11: Pattern appears for two weeks only | B11: Wait for more data | C11: Wait for more data
A12: You want to switch a whole day off | B12: Test first: reduce that day for four weeks, watch total weekly leads | C12: Test first, ideally as a campaign experiment, and watch total weekly leads
A14: THE DECISION RULE
A15: Adjust a day only when the pattern repeats for at least eight weeks, holds on conversions and not just clicks, and survives a check on lead quality. Then change one thing, test it, and measure the whole week.
A17: Sources
A18: Google Ads Help: About ad scheduling
A19: Google Ads Help: About bid adjustments (Smart Bidding and ad schedule adjustments)
A20: Google Ads Help: Data discrepancies (conversions reported on the ad impression date)
A22: MagicWorks IT Solutions · Evolving with Purpose
